<mujoco model="panda">
  <compiler angle="radian" discardvisual="false" meshdir="../meshes_panda/for_mujoco/" />
	<option timestep="0.002">
      <flag warmstart="enable" />
	</option>
      <asset>
    <texture builtin="gradient" height="32" rgb1="0.26 0.58 0.51" rgb2="0.26 0.58 0.51" type="skybox" width="32" />  </asset>
  <size nconmax="2000" njmax="500" />
  <visual>
    <map zfar="1000" znear="0.001" />
  </visual>
  <worldbody>
    <geom name="ground" pos="0 0 -0.4" rgba="0.7 0.6 0.5 1" size="4 4 .05" type="plane" />
    <light castshadow="false" cutoff="100" diffuse="1 1 1" dir="-0 0 -1.3" directional="true" exponent="1" pos="0 0 1.3" specular=".1 .1 .1" />
    <camera euler="0 0 0" fovy="45" ipd="0.0" mode="fixed" name="rgbd_cage" pos="0.7 0.1 0.9" />
      <body name="puck" pos="[puck_pos]">
      <joint name="box:x_joint" damping="0.05" type="slide" axis="1 0 0"/>
      <joint name="box:y_joint" damping="0.05" type="slide" axis="0 1 0"/>
      <joint name="box:z_joint" damping="0.05" type="slide" axis="0 0 1"/>
      <geom condim="1"
            density="1000"
            friction="0 0 0"
            name="box:geom1"
            pos="0 0 0"
            priority="1"
            rgba="0.32 0.32 0.32 1"
            size="[puck_size]"
            solimp="0.998 0.998 0.001"
            solref="0.002 1"
            type="cylinder" />
    </body>
    <body name="panda_ground" pos="0 0 0">
        <geom type="box" size="0.18 0.18 0.01" rgba=".9 .9 .9 1"/>
    </body>
    <body name="table" pos="0.5 0 -0.2">
        <geom type="box" size="0.7 0.2 0.2" rgba=".9 .9 .9 1"/>
    </body>
  </worldbody>
      <actuator>
        <motor ctrllimited="true" forcelimited="true" ctrlrange="-1 1" forcerange="-87 87"
        joint="box:x_joint" name="puck_x_motor" />
        <motor ctrllimited="true" forcelimited="true" ctrlrange="-1 1" forcerange="-87 87"
        joint="box:y_joint" name="puck_y_motor" />
    </actuator>
</mujoco>